#VRML_SIM R2022a utf8
WorldInfo {
}
Viewpoint {
  orientation -0.1456569836601233 0.27908871417088277 0.9491541143215246 1.0054911908033017
  position 6.910147703138918 -5.8047031980179575 6.5132210368743
}
TexturedBackground {
}
TexturedBackgroundLight {
}
Robot {
  translation 13.13470583124153 0.23195151891500576 4.5890024186779605
  rotation 0.004419772709250509 -0.02399842193484028 0.9997022263423425 2.1475142586856237
  children [
    DEF base Shape {
      appearance PaintedWood {
        colorOverride 0 0.2 0.1
      }
      geometry DEF Base Box {
        size 1.2 3 1
      }
    }
    Solid {
      translation 0 -1.26 0.55
      children [
        DEF cam_stand Shape {
          appearance PBRAppearance {
            baseColor 0.3 0.3 0.3
          }
          geometry Box {
            size 0.3 0.3 0.1
          }
        }
        Camera {
          translation 0 0 0.13
          rotation 0 0 1 -1.5707953071795862
          children [
            DEF cam Shape {
              appearance PBRAppearance {
              }
              geometry Box {
                size 0.1 0.1 0.1
              }
            }
          ]
          boundingObject USE cam
          physics Physics {
            mass 1
          }
        }
      ]
      name "solid(4)"
      boundingObject USE cam_stand
      physics Physics {
        mass 1
      }
    }
    DistanceSensor {
      translation 0.35 -1.5 0
      rotation 0 0 1 -1.5707853071795865
      children [
        DEF ds Shape {
          appearance PBRAppearance {
            baseColor 1 1 0
            metalness 0
          }
          geometry Sphere {
            radius 0.1
          }
        }
      ]
      name "ds_right"
      boundingObject DEF ds Shape {
        appearance PBRAppearance {
          baseColor 1 1 0
          metalness 0
        }
        geometry Sphere {
          radius 0.1
        }
      }
      physics DEF phy2 Physics {
        mass 1
      }
      lookupTable [
        0 0 0
        3 1000 0
      ]
      numberOfRays 2
    }
    DistanceSensor {
      translation -0.35 -1.5 0
      rotation 0 0 -1 1.57079
      children [
        DEF ds Shape {
          appearance PBRAppearance {
            baseColor 1 1 0
            metalness 0
          }
          geometry Sphere {
            radius 0.1
          }
        }
      ]
      name "ds_left"
      lookupTable [
        0 0 0
        3 1000 0
      ]
      numberOfRays 2
    }
    DEF wheel1 HingeJoint {
      jointParameters HingeJointParameters {
        position 584.9004001651583
        anchor 0.75 -0.96 -0.53
      }
      device [
        RotationalMotor {
          name "wheel1"
          maxTorque 50
        }
      ]
      endPoint Solid {
        translation 0.7500545661775462 -0.9599894439638827 -0.5299858857406531
        rotation -0.2643942289702679 -0.9274624439668199 -0.2644033031531776 4.637148664880039
        children [
          DEF wheel Shape {
            appearance Rubber {
            }
            geometry Cylinder {
              height 0.5
              radius 0.5
            }
          }
        ]
        boundingObject USE wheel
        physics DEF phy1 Physics {
          mass 1
        }
        linearVelocity 1.6822572266005384 1.0893247286295307 0.06591199178249822
        angularVelocity -2.1819894709176446 3.3631891999227657 0.10782747366922157
      }
    }
    DEF wheel2 HingeJoint {
      jointParameters HingeJointParameters {
        position 651.6385917307249
        anchor -0.75 -0.96 -0.53
      }
      device [
        RotationalMotor {
          name "wheel2"
          maxTorque 50
        }
      ]
      endPoint Solid {
        translation -0.7500442815454464 -0.9600275844376084 -0.5300306977032947
        rotation 0.6192603232321665 -0.48274124629216064 0.6192556347734626 4.041054309951402
        children [
          DEF wheel Shape {
            appearance Rubber {
            }
            geometry Cylinder {
              height 0.5
              radius 0.5
            }
          }
        ]
        name "solid(1)"
        boundingObject USE wheel
        physics USE phy1
        linearVelocity 1.6822645883432579 1.0896139128239404 0.05744639814070703
        angularVelocity -2.1820204014323914 3.3631828051182344 0.10781910956902534
      }
    }
    DEF wheel3 HingeJoint {
      jointParameters HingeJointParameters {
        position 569.0106474245035
        anchor 0.75 0.96 -0.53
      }
      device [
        RotationalMotor {
          name "wheel3"
          maxTorque 50
        }
      ]
      endPoint Solid {
        translation 0.7500226838697834 0.9599405234722665 -0.5300055468459451
        rotation 0.7008615654351198 -0.13257696244355952 0.7008683293779739 3.405204864166622
        children [
          DEF wheel Shape {
            appearance Rubber {
            }
            geometry Cylinder {
              height 0.5
              radius 0.5
            }
          }
        ]
        name "solid(2)"
        boundingObject USE wheel
        physics USE phy1
        linearVelocity 1.6820184142598693 1.0885441718232518 0.08549491612020635
        angularVelocity -2.1820153371463062 3.3631722643852 0.10782432297934628
      }
    }
    DEF wheel4 HingeJoint {
      jointParameters HingeJointParameters {
        position 644.296307233297
        anchor -0.75 0.96 -0.53
      }
      device [
        RotationalMotor {
          name "wheel4"
          maxTorque 50
        }
      ]
      endPoint Solid {
        translation -0.7500744885430137 0.9600027665308821 -0.530059652691331
        rotation 0.7039906962145307 -0.09390458039822162 0.7039737419986729 3.3288146933478813
        children [
          DEF wheel Shape {
            appearance Rubber {
            }
            geometry Cylinder {
              height 0.5
              radius 0.5
            }
          }
        ]
        name "solid(3)"
        boundingObject USE wheel
        physics USE phy1
        linearVelocity 1.6819284290973702 1.0887280783316404 0.07776297078878376
        angularVelocity -2.1820053954902328 3.363148513514399 0.10782120798741773
      }
    }
  ]
  boundingObject USE base
  physics USE phy1
  controller "forest_controller"
  linearVelocity 1.6937929006286394 1.0907960703148576 0.058423142471378135
  angularVelocity -0.0011753832558780708 0.011693078255043765 0.00047260706594687155
}
DEF forest Solid {
  children [
    Pine {
      translation -15.62 20.85 1.15
      name "pine tree(6)"
    }
    Pine {
      translation -15.62 -10.45 1.15
      name "pine tree(5)"
    }
    Pine {
      translation 11.67 -10.45 1.45
      name "pine tree(3)"
    }
    Pine {
      translation 20.49 -10.45 2.81
      name "pine tree(4)"
    }
    Pine {
      translation 11.67 15.84 1.88
      name "pine tree(2)"
    }
    Pine {
      translation -4.35 9.25 2.22
      name "pine tree(1)"
    }
    Pine {
      translation -4.35 -3.53 2.18
    }
    SimpleTree {
      translation 0 0 3
    }
    SimpleTree {
      translation 6 0 3
      name "tree(1)"
    }
    SimpleTree {
      translation 6 10 3
      name "tree(2)"
    }
    SimpleTree {
      translation 16 15 3
      name "tree(3)"
    }
    SimpleTree {
      translation -16 -15 1.8
      name "tree(4)"
    }
    SimpleTree {
      translation 16 -15 3
      name "tree(5)"
    }
    SimpleTree {
      translation 5 -22 2
      name "tree(6)"
    }
    SimpleTree {
      translation -15 -22 2
      name "tree(7)"
    }
    SimpleTree {
      translation -9 22 2
      name "tree(8)"
    }
    SimpleTree {
      translation -18 16 2.5
      name "tree(9)"
    }
    SimpleTree {
      translation -22 -3 2
      name "tree(10)"
    }
    SimpleTree {
      translation 10 -8 3
      name "tree(11)"
    }
    SimpleTree {
      translation -5 -8 2.3
      name "tree(12)"
    }
    SimpleTree {
      translation 1 -17 2
      name "tree(13)"
    }
    Oak {
      translation 14.94 0 3.24
    }
    Oak {
      translation 20 -5.97 3.28
      name "oak tree(1)"
    }
    Oak {
      translation 15.97 -10.75 3.02
      name "oak tree(2)"
    }
    Oak {
      translation 15.97 11.04 3.07
      name "oak tree(3)"
    }
    Oak {
      translation -24.52 6.27 2.46
      name "oak tree(4)"
    }
    Oak {
      translation -12.06 2.39 2.09
      name "oak tree(6)"
    }
    Oak {
      translation -13.84 10.96 2.09
      name "oak tree(7)"
    }
    Oak {
      translation -2.97 18.97 1.79
      name "oak tree(8)"
    }
    Oak {
      translation 0.35 13.07 2.24
      name "oak tree(9)"
    }
    Oak {
      translation -9.22 15.64 2.72
      name "oak tree(5)"
    }
    Oak {
      translation 7.46 20.45 2.43
      name "oak tree(10)"
    }
    Oak {
      translation 16.74 21.4 2.43
      name "oak tree(11)"
    }
    BigSassafras {
      translation -11.82 -13.71 1.72
    }
    BigSassafras {
      translation -21.32 -8.95 1.72
      name "sassafras tree(1)"
    }
    BigSassafras {
      translation 19.67 7.95 3.44
      name "sassafras tree(2)"
    }
    BigSassafras {
      translation 19.67 -1.13 2.97
      name "sassafras tree(3)"
    }
    BigSassafras {
      translation 21.66 -19.93 2.97
      name "sassafras tree(4)"
    }
    BigSassafras {
      translation 9.84 -19.93 2.64
      name "sassafras tree(5)"
    }
    BigSassafras {
      translation -6.69 -19.93 1.29
      name "sassafras tree(6)"
    }
    BigSassafras {
      translation -16.82 -5.16 2.98
      name "sassafras tree(7)"
    }
    BigSassafras {
      translation -16.82 8.12 2.98
      name "sassafras tree(8)"
    }
    BigSassafras {
      translation -21.82 21.14 2.98
      name "sassafras tree(9)"
    }
    BigSassafras {
      translation 1.95 21.14 2.63
      name "sassafras tree(10)"
    }
    Cypress {
      translation -11.36 0 1.96
    }
    Cypress {
      translation -14.16 5.78 2.06
      name "cypress tree(1)"
    }
    Cypress {
      translation 20.42 15.8 3.01
      name "cypress tree(2)"
    }
    Cypress {
      translation 21.87 20.79 3.01
      name "cypress tree(3)"
    }
    Cypress {
      translation 11.51 1.81 3.01
      name "cypress tree(4)"
    }
    Cypress {
      translation 2.77 -10.75 2.51
      name "cypress tree(5)"
    }
    Cypress {
      translation -2.24 -21.57 1.87
      name "cypress tree(6)"
    }
    Cypress {
      translation 15.22 -21.57 2.5
      name "cypress tree(7)"
    }
    Cypress {
      translation 6.61 -15.53 2.8
      name "cypress tree(8)"
    }
    Cypress {
      translation -11.26 5.51 2.26
      name "cypress tree(9)"
    }
  ]
}
UnevenTerrain {
}
DEF Border Solid {
  translation 0 0 3.9
  children [
    Solid {
      translation -1.379260504278638e-07 -25.20000062547894 -0.37006283297071896
      rotation -0.030209004805946158 -0.10649179629174299 0.9938545735424233 1.1643902325295495e-05
      children [
        DEF border Shape {
          appearance DryMud {
          }
          geometry Box {
            size 49 1 3
          }
        }
      ]
      name "border1"
      boundingObject USE border
      physics DEF phy1 Physics {
        mass 1
      }
      linearVelocity -1.7575321597474177e-17 -4.440892098500626e-14 -1.201621557811398e-10
      angularVelocity -1.926154551989355e-17 7.902742945715486e-14 1.1490124796459509e-13
    }
    Solid {
      translation 0 25.53 -0.37006275289589663
      rotation 0 1 0 0
      children [
        DEF border Shape {
          appearance DryMud {
          }
          geometry Box {
            size 49 1 3
          }
        }
      ]
      name "border2"
      boundingObject USE border
      physics USE phy1
      linearVelocity 0 0 -1.2016215578114642e-10
    }
    Solid {
      translation 25.53 0 -0.37
      rotation 0 0 1 1.5708
      children [
        DEF border Shape {
          appearance DryMud {
          }
          geometry Box {
            size 49 1 3
          }
        }
      ]
      name "border3"
      boundingObject USE border
    }
    Solid {
      translation -25.5301 1.57462e-05 -0.37006275289589663
      rotation 5.1580022398749126e-05 -9.550089548459884e-05 0.9999999941095401 1.569814080916819
      children [
        DEF border Shape {
          appearance DryMud {
          }
          geometry Box {
            size 49 1 3
          }
        }
      ]
      name "border4"
      boundingObject USE border
      physics USE phy1
      linearVelocity 0 0 -1.2016215578114642e-10
    }
  ]
  name "solid(1)"
}
